Workbook

Sheet Comparador exposicion
A1: Estrategia | B1: Expo. acciones | C1: Ret. total | D1: CAGR | E1: Volatilidad | F1: Sharpe | G1: Sortino | H1: Max Drawdown | I1: Calmar
A2: SPY (Buy & Hold) | B2: 100% | C2: 366.5% | D2: 15.6% | E2: 17.7% | F2: 0.91 | G2: 1.10 | H2: -33.7% | I2: 0.46
A3: Estrategia completa | B3: 67% | C3: 17.9% | D3: 1.6% | E3: 10.8% | F3: 0.20 | G3: 0.23 | H3: -18.1% | I3: 0.09
A4: Top 3 sin filtro (siempre invertido) | B4: 100% | C4: 116.4% | D4: 7.5% | E4: 16.9% | F4: 0.52 | G4: 0.62 | H4: -32.2% | I4: 0.23
A5: Exposicion similar dinamica (en SPY) | B5: 67% | C5: 76.4% | D5: 5.5% | E5: 10.1% | F5: 0.58 | G5: 0.66 | H5: -25.8% | I5: 0.21
A6: Exposicion estatica 67% SPY / 33% BIL | B6: 67% | C6: 212.5% | D6: 11.3% | E6: 11.3% | F6: 1.01 | G6: 1.21 | H6: -22.3% | I6: 0.51

Sheet Motivos resumen
A1: Motivo | B1: Cantidad
A2: --- ENTRADAS --- | B2: 137
A3: ruptura techo Donchian +0.3% & Top 3 | B3: 137
A4: --- SALIDAS --- | B4: 136
A5: ruptura piso Donchian | B5: 101
A6: cae del ranking (>#5) | B6: 33
A7: ruptura piso Donchian + cae del ranking (>#5) | B7: 2

Sheet Motivos detalle
A1: Fecha | B1: Activo | C1: Accion | D1: Motivo | E1: Rank | F1: Momentum_12m | G1: Cierre | H1: Donchian_ref
A2: 42425 | B2: XLU | C2: ENTRA | D2: ruptura techo Donchian +0.3% & Top 3 | E2: 1 | F2: 0.0805 | G2: 17.03 | H2: 16.89
A3: 42425 | B3: XLP | C3: ENTRA | D3: ruptura techo Donchian +0.3% & Top 3 | E3: 2 | F3: 0.0693 | G3: 39.18 | H3: 38.79
A4: 42430 | B4: XLY | C4: ENTRA | D4: ruptura techo Donchian +0.3% & Top 3 | E4: 3 | F4: 0.0083 | G4: 34.17 | H4: 33.73
A5: 42480 | B5: XLU | C5: SALE | D5: ruptura piso Donchian | E5: 1 | F5: 0.1203 | G5: 17.32 | H5: 17.42
A6: 42481 | B6: XLP | C6: SALE | D6: ruptura piso Donchian | E6: 2 | F6: 0.0757 | G6: 39.35 | H6: 39.63
A7: 42500 | B7: XLP | C7: ENTRA | D7: ruptura techo Donchian +0.3% & Top 3 | E7: 2 | F7: 0.132 | G7: 41.09 | H7: 40.8
A8: 42503 | B8: XLY | C8: SALE | D8: ruptura piso Donchian | E8: 3 | F8: 0.0437 | G8: 35.07 | H8: 35.15
A9: 42524 | B9: XLU | C9: ENTRA | D9: ruptura techo Donchian +0.3% & Top 3 | E9: 1 | F9: 0.2004 | G9: 18.1 | H9: 17.98
A10: 42562 | B10: XLK | C10: ENTRA | D10: ruptura techo Donchian +0.3% & Top 3 | E10: 3 | F10: 0.0922 | G10: 19.98 | H10: 19.88
A11: 42587 | B11: XLU | C11: SALE | D11: ruptura piso Donchian | E11: 1 | F11: 0.1985 | G11: 18.48 | H11: 18.64
A12: 42605 | B12: XLB | C12: ENTRA | D12: ruptura techo Donchian +0.3% & Top 3 | E12: 3 | F12: 0.2182 | G12: 20.2 | H12: 20.14
A13: 42622 | B13: XLP | C13: SALE | D13: ruptura piso Donchian | E13: 3 | F13: 0.1545 | G13: 40.29 | H13: 41.33
... A274: 46275 | B274: XLV | C274: SALE | D274: ruptura piso Donchian | E274: 3 | F274: 0.2162 | G274: 165.66 | H274: 165.76

Sheet Parametros
A1: Parámetros del análisis
A3: Parámetro | B3: Valor | C3: Comentario
A4: Ventana whipsaw (días corridos) | B4: 10 | C4: Salida seguida de reentrada del mismo activo dentro de esta ventana
A5: Margen de entrada sobre techo Donchian | B5: 0.003 | C5: El que usa la estrategia para entrar (+0,3%)
A6: Margen propuesto para piso Donchian | B6: 0.003 | C6: Margen igual al de la entrada; se usa en Sensibilidad Donchian
A7: Umbral momentum absoluto (filtro 1) | B7: 0 | C7: Solo entrar si Momentum 12m > este valor
A9: Tasa BIL / T-Bill 3m por año (filtro 2)
A10: Año | B10: Tasa anual aprox. | C10: Comentario
A11: 2016 | B11: 0.003 | C11: Supuesto aproximado (promedio anual T-Bill 3m)
A12: 2017 | B12: 0.009
A13: 2018 | B13: 0.019
A14: 2019 | B14: 0.021
A15: 2020 | B15: 0.004
A16: 2021 | B16: 0.0005
A17: 2022 | B17: 0.02
A18: 2023 | B18: 0.051
A19: 2024 | B19: 0.05
A20: 2025 | B20: 0.042
A21: 2026 | B21: 0.037
A23: Tramos de momentum 12m
A24: Desde | B24: Tramo | C24: Comentario
A25: -10 | B25: Negativo | C25: Límite inferior de cada tramo (búsqueda aproximada)
A26: 0 | B26: 0% a 5%
A27: 0.05 | B27: 5% a 15%
A28: 0.15 | B28: 15% a 30%
A29: 0.3 | B29: Más de 30%
A31: Costos de transacción
A32: Comisión por operación (compra o venta) | B32: 0.002 | C32: Se cobra en cada compra y en cada venta (ida y vuelta = 2 comisiones)
A33: Posiciones simultáneas (Top N) | B33: 3 | C33: Cada trade pesa 1/N del capital; se usa para llevar el costo a nivel cartera

Sheet Trades
A1: Tabla de trades (cada entrada con su salida)
A2: Retorno = cierre de salida / cierre de entrada − 1 (precios de la señal). Días = días corridos. Costo whipsaw > 0 = recompró más caro de lo que vendió.
A3: # | B3: Fila entrada | C3: Activo | D3: Fecha entrada | E3: Rank entrada | F3: Momentum 12m entrada | G3: Cierre entrada | H3: Techo Donchian | I3: Margen s/ techo | J3: Fila salida | K3: Fecha salida | L3: Cierre salida | M3: Ref. Donchian salida | N3: Motivo salida | O3: Rank salida | P3: Días | Q3: Retorno | R3: Resultado | S3: Tramo momentum | T3: Dist. al piso en salida | U3: Fila reentrada | V3: Fecha reentrada | W3: Días hasta reentrada | X3: Cierre reentrada | Y3: Whipsaw | Z3: Costo whipsaw | AA3: Pasa filtro mom. > umbral | AB3: Tasa BIL del año | AC3: Pasa filtro mom. > BIL | AD3: Salida evitable con margen piso | AE3: Retorno neto comisión | AF3: Costo comisión
A4: =ROW()-3 -> 1 | B4: {=IFERROR(_xlfn.AGGREGATE(15,6,ROW('Motivos detalle'!$C$2:$C$274)/('Motivos detalle'!$C$2:$C$274="ENTRA"),A4),"")} -> 2 | C4: {=INDEX('Motivos detalle'!$B:$B,$B4)} -> XLU | D4: {=INDEX('Motivos detalle'!$A:$A,$B4)} -> 42425 | E4: {=INDEX('Motivos detalle'!$E:$E,$B4)} -> 1 | F4: {=INDEX('Motivos detalle'!$F:$F,$B4)} -> 0.0805 | G4: {=INDEX('Motivos detalle'!$G:$G,$B4)} -> 17.03 | H4: {=INDEX('Motivos detalle'!$H:$H,$B4)} -> 16.89 | I4: =G4/H4-1 -> 0.0082889284 | J4: {=IFERROR(_xlfn.AGGREGATE(15,6,ROW('Motivos detalle'!$C$2:$C$274)/(('Motivos detalle'!$C$2:$C$274="SALE")*('Motivos detalle'!$B$2:$B$274=C4)*(ROW('Motivos detalle'!$C$2:$C$274)>B4)),1),"")} -> 5 | K4: {=IF($J4="","",INDEX('Motivos detalle'!$A:$A,$J4))} -> 42480 | L4: {=IF($J4="","",INDEX('Motivos detalle'!$G:$G,$J4))} -> 17.32 | M4: {=IF($J4="","",INDEX('Motivos detalle'!$H:$H,$J4))} -> 17.42 | N4: {=IF($J4="","Abierto",INDEX('Motivos detalle'!$D:$D,$J4))} -> ruptura piso Donchian | O4: {=IF($J4="","",INDEX('Motivos detalle'!$E:$E,$J4))} -> 1 | P4: =IF(J4="","",K4-D4) -> 55 | Q4: =IF(J4="","",L4/G4-1) -> 0.017028773 | R4: =IF(J4="","Abierto",IF(Q4>0,"Ganador","Perdedor")) -> Ganador | S4: =VLOOKUP(F4,Parametros!$A$25:$B$29,2,TRUE) -> 5% a 15% | T4: =IF(ISNUMBER(SEARCH("piso",N4)),L4/M4-1,"") -> -0.0057405281 | U4: {=IF(J4="","",IFERROR(_xlfn.AGGREGATE(15,6,ROW('Motivos detalle'!$C$2:$C$274)/(('Motivos detalle'!$C$2:$C$274="ENTRA")*('Motivos detalle'!$B$2:$B$274=C4)*(ROW('Motivos detalle'!$C$2:$C$274)>J4)),1),""))} -> 9 | V4: {=IF(U4="","",INDEX('Motivos detalle'!$A:$A,U4))} -> 42524 | W4: =IF(V4="","",V4-K4) -> 44 | X4: {=IF(U4="","",INDEX('Motivos detalle'!$G:$G,U4))} -> 18.1 | Y4: =IF(W4="","No",IF(W4<Parametros!$B$4,"Sí","No")) -> No | Z4: =IF(Y4="Sí",X4/L4-1,"") | AA4: =IF(F4>Parametros!$B$7,"Sí","No") -> Sí | AB4: =VLOOKUP(YEAR(D4),Parametros!$A$11:$B$21,2,FALSE) -> 0.003 | AC4: =IF(F4>AB4,"Sí","No") -> Sí | AD4: =IF(N4="ruptura piso Donchian",IF(T4>-Parametros!$B$6,"Sí","No"),"") -> No | AE4: =IF(J4="","",(L4*(1-Parametros!$B$32))/(G4*(1+Parametros!$B$32))-1) -> 0.012968778 | AF4: =IF(J4="","",Q4-AE4) -> 0.0040599951
A5: =ROW()-3 -> 2 | B5: {=IFERROR(_xlfn.AGGREGATE(15,6,ROW('Motivos detalle'!$C$2:$C$274)/('Motivos detalle'!$C$2:$C$274="ENTRA"),A5),"")} -> 3 | C5: {=INDEX('Motivos detalle'!$B:$B,$B5)} -> XLP | D5: {=INDEX('Motivos detalle'!$A:$A,$B5)} -> 42425 | E5: {=INDEX('Motivos detalle'!$E:$E,$B5)} -> 2 | F5: {=INDEX('Motivos detalle'!$F:$F,$B5)} -> 0.0693 | G5: {=INDEX('Motivos detalle'!$G:$G,$B5)} -> 39.18 | H5: {=INDEX('Motivos detalle'!$H:$H,$B5)} -> 38.79 | I5: =G5/H5-1 -> 0.010054138 | J5: {=IFERROR(_xlfn.AGGREGATE(15,6,ROW('Motivos detalle'!$C$2:$C$274)/(('Motivos detalle'!$C$2:$C$274="SALE")*('Motivos detalle'!$B$2:$B$274=C5)*(ROW('Motivos detalle'!$C$2:$C$274)>B5)),1),"")} -> 6 | K5: {=IF($J5="","",INDEX('Motivos detalle'!$A:$A,$J5))} -> 42481 | L5: {=IF($J5="","",INDEX('Motivos detalle'!$G:$G,$J5))} -> 39.35 | M5: {=IF($J5="","",INDEX('Motivos detalle'!$H:$H,$J5))} -> 39.63 | N5: {=IF($J5="","Abierto",INDEX('Motivos detalle'!$D:$D,$J5))} -> ruptura piso Donchian | O5: {=IF($J5="","",INDEX('Motivos detalle'!$E:$E,$J5))} -> 2 | P5: =IF(J5="","",K5-D5) -> 56 | Q5: =IF(J5="","",L5/G5-1) -> 0.0043389484 | R5: =IF(J5="","Abierto",IF(Q5>0,"Ganador","Perdedor")) -> Ganador | S5: =VLOOKUP(F5,Parametros!$A$25:$B$29,2,TRUE) -> 5% a 15% | T5: =IF(ISNUMBER(SEARCH("piso",N5)),L5/M5-1,"") -> -0.0070653545 | U5: {=IF(J5="","",IFERROR(_xlfn.AGGREGATE(15,6,ROW('Motivos detalle'!$C$2:$C$274)/(('Motivos detalle'!$C$2:$C$274="ENTRA")*('Motivos detalle'!$B$2:$B$274=C5)*(ROW('Motivos detalle'!$C$2:$C$274)>J5)),1),""))} -> 7 | V5: {=IF(U5="","",INDEX('Motivos detalle'!$A:$A,U5))} -> 42500 | W5: =IF(V5="","",V5-K5) -> 19 | X5: {=IF(U5="","",INDEX('Motivos detalle'!$G:$G,U5))} -> 41.09 | Y5: =IF(W5="","No",IF(W5<Parametros!$B$4,"Sí","No")) -> No | Z5: =IF(Y5="Sí",X5/L5-1,"") | AA5: =IF(F5>Parametros!$B$7,"Sí","No") -> Sí | AB5: =VLOOKUP(YEAR(D5),Parametros!$A$11:$B$21,2,FALSE) -> 0.003 | AC5: =IF(F5>AB5,"Sí","No") -> Sí | AD5: =IF(N5="ruptura piso Donchian",IF(T5>-Parametros!$B$6,"Sí","No"),"") -> No | AE5: =IF(J5="","",(L5*(1-Parametros!$B$32))/(G5*(1+Parametros!$B$32))-1) -> 0.00032961132 | AF5: =IF(J5="","",Q5-AE5) -> 0.0040093371
A6: =ROW()-3 -> 3 | B6: {=IFERROR(_xlfn.AGGREGATE(15,6,ROW('Motivos detalle'!$C$2:$C$274)/('Motivos detalle'!$C$2:$C$274="ENTRA"),A6),"")} -> 4 | C6: {=INDEX('Motivos detalle'!$B:$B,$B6)} -> XLY | D6: {=INDEX('Motivos detalle'!$A:$A,$B6)} -> 42430 | E6: {=INDEX('Motivos detalle'!$E:$E,$B6)} -> 3 | F6: {=INDEX('Motivos detalle'!$F:$F,$B6)} -> 0.0083 | G6: {=INDEX('Motivos detalle'!$G:$G,$B6)} -> 34.17 | H6: {=INDEX('Motivos detalle'!$H:$H,$B6)} -> 33.73 | I6: =G6/H6-1 -> 0.013044767 | J6: {=IFERROR(_xlfn.AGGREGATE(15,6,ROW('Motivos detalle'!$C$2:$C$274)/(('Motivos detalle'!$C$2:$C$274="SALE")*('Motivos detalle'!$B$2:$B$274=C6)*(ROW('Motivos detalle'!$C$2:$C$274)>B6)),1),"")} -> 8 | K6: {=IF($J6="","",INDEX('Motivos detalle'!$A:$A,$J6))} -> 42503 | L6: {=IF($J6="","",INDEX('Motivos detalle'!$G:$G,$J6))} -> 35.07 | M6: {=IF($J6="","",INDEX('Motivos detalle'!$H:$H,$J6))} -> 35.15 | N6: {=IF($J6="","Abierto",INDEX('Motivos detalle'!$D:$D,$J6))} -> ruptura piso Donchian | O6: {=IF($J6="","",INDEX('Motivos detalle'!$E:$E,$J6))} -> 3 | P6: =IF(J6="","",K6-D6) -> 73 | Q6: =IF(J6="","",L6/G6-1) -> 0.026338894 | R6: =IF(J6="","Abierto",IF(Q6>0,"Ganador","Perdedor")) -> Ganador | S6: =VLOOKUP(F6,Parametros!$A$25:$B$29,2,TRUE) -> 0% a 5% | T6: =IF(ISNUMBER(SEARCH("piso",N6)),L6/M6-1,"") -> -0.0022759602 | U6: {=IF(J6="","",IFERROR(_xlfn.AGGREGATE(15,6,ROW('Motivos detalle'!$C$2:$C$274)/(('Motivos detalle'!$C$2:$C$274="ENTRA")*('Motivos detalle'!$B$2:$B$274=C6)*(ROW('Motivos detalle'!$C$2:$C$274)>J6)),1),""))} -> 60 | V6: {=IF(U6="","",INDEX('Motivos detalle'!$A:$A,U6))} -> 43256 | W6: =IF(V6="","",V6-K6) -> 753 | X6: {=IF(U6="","",INDEX('Motivos detalle'!$G:$G,U6))} -> 50.1 | Y6: =IF(W6="","No",IF(W6<Parametros!$B$4,"Sí","No")) -> No | Z6: =IF(Y6="Sí",X6/L6-1,"") | AA6: =IF(F6>Parametros!$B$7,"Sí","No") -> Sí | AB6: =VLOOKUP(YEAR(D6),Parametros!$A$11:$B$21,2,FALSE) -> 0.003 | AC6: =IF(F6>AB6,"Sí","No") -> Sí | AD6: =IF(N6="ruptura piso Donchian",IF(T6>-Parametros!$B$6,"Sí","No"),"") -> Sí | AE6: =IF(J6="","",(L6*(1-Parametros!$B$32))/(G6*(1+Parametros!$B$32))-1) -> 0.022241733 | AF6: =IF(J6="","",Q6-AE6) -> 0.0040971613
A7: =ROW()-3 -> 4 | B7: {=IFERROR(_xlfn.AGGREGATE(15,6,ROW('Motivos detalle'!$C$2:$C$274)/('Motivos detalle'!$C$2:$C$274="ENTRA"),A7),"")} -> 7 | C7: {=INDEX('Motivos detalle'!$B:$B,$B7)} -> XLP | D7: {=INDEX('Motivos detalle'!$A:$A,$B7)} -> 42500 | E7: {=INDEX('Motivos detalle'!$E:$E,$B7)} -> 2 | F7: {=INDEX('Motivos detalle'!$F:$F,$B7)} -> 0.132 | G7: {=INDEX('Motivos detalle'!$G:$G,$B7)} -> 41.09 | H7: {=INDEX('Motivos detalle'!$H:$H,$B7)} -> 40.8 | I7: =G7/H7-1 -> 0.0071078431 | J7: {=IFERROR(_xlfn.AGGREGATE(15,6,ROW('Motivos detalle'!$C$2:$C$274)/(('Motivos detalle'!$C$2:$C$274="SALE")*('Motivos detalle'!$B$2:$B$274=C7)*(ROW('Motivos detalle'!$C$2:$C$274)>B7)),1),"")} -> 13 | K7: {=IF($J7="","",INDEX('Motivos detalle'!$A:$A,$J7))} -> 42622 | L7: {=IF($J7="","",INDEX('Motivos detalle'!$G:$G,$J7))} -> 40.29 | M7: {=IF($J7="","",INDEX('Motivos detalle'!$H:$H,$J7))} -> 41.33 | N7: {=IF($J7="","Abierto",INDEX('Motivos detalle'!$D:$D,$J7))} -> ruptura piso Donchian | O7: {=IF($J7="","",INDEX('Motivos detalle'!$E:$E,$J7))} -> 3 | P7: =IF(J7="","",K7-D7) -> 122 | Q7: =IF(J7="","",L7/G7-1) -> -0.019469457 | R7: =IF(J7="","Abierto",IF(Q7>0,"Ganador","Perdedor")) -> Perdedor | S7: =VLOOKUP(F7,Parametros!$A$25:$B$29,2,TRUE) -> 5% a 15% | T7: =IF(ISNUMBER(SEARCH("piso",N7)),L7/M7-1,"") -> -0.02516332 | U7: {=IF(J7="","",IFERROR(_xlfn.AGGREGATE(15,6,ROW('Motivos detalle'!$C$2:$C$274)/(('Motivos detalle'!$C$2:$C$274="ENTRA")*('Motivos detalle'!$B$2:$B$274=C7)*(ROW('Motivos detalle'!$C$2:$C$274)>J7)),1),""))} -> 82 | V7: {=IF(U7="","",INDEX('Motivos detalle'!$A:$A,U7))} -> 43623 | W7: =IF(V7="","",V7-K7) -> 1001 | X7: {=IF(U7="","",INDEX('Motivos detalle'!$G:$G,U7))} -> 48.32 | Y7: =IF(W7="","No",IF(W7<Parametros!$B$4,"Sí","No")) -> No | Z7: =IF(Y7="Sí",X7/L7-1,"") | AA7: =IF(F7>Parametros!$B$7,"Sí","No") -> Sí | AB7: =VLOOKUP(YEAR(D7),Parametros!$A$11:$B$21,2,FALSE) -> 0.003 | AC7: =IF(F7>AB7,"Sí","No") -> Sí | AD7: =IF(N7="ruptura piso Donchian",IF(T7>-Parametros!$B$6,"Sí","No"),"") -> No | AE7: =IF(J7="","",(L7*(1-Parametros!$B$32))/(G7*(1+Parametros!$B$32))-1) -> -0.023383751 | AF7: =IF(J7="","",Q7-AE7) -> 0.0039142936
A8: =ROW()-3 -> 5 | B8: {=IFERROR(_xlfn.AGGREGATE(15,6,ROW('Motivos detalle'!$C$2:$C$274)/('Motivos detalle'!$C$2:$C$274="ENTRA"),A8),"")} -> 9 | C8: {=INDEX('Motivos detalle'!$B:$B,$B8)} -> XLU | D8: {=INDEX('Motivos detalle'!$A:$A,$B8)} -> 42524 | E8: {=INDEX('Motivos detalle'!$E:$E,$B8)} -> 1 | F8: {=INDEX('Motivos detalle'!$F:$F,$B8)} -> 0.2004 | G8: {=INDEX('Motivos detalle'!$G:$G,$B8)} -> 18.1 | H8: {=INDEX('Motivos detalle'!$H:$H,$B8)} -> 17.98 | I8: =G8/H8-1 -> 0.0066740823 | J8: {=IFERROR(_xlfn.AGGREGATE(15,6,ROW('Motivos detalle'!$C$2:$C$274)/(('Motivos detalle'!$C$2:$C$274="SALE")*('Motivos detalle'!$B$2:$B$274=C8)*(ROW('Motivos detalle'!$C$2:$C$274)>B8)),1),"")} -> 11 | K8: {=IF($J8="","",INDEX('Motivos detalle'!$A:$A,$J8))} -> 42587 | L8: {=IF($J8="","",INDEX('Motivos detalle'!$G:$G,$J8))} -> 18.48 | M8: {=IF($J8="","",INDEX('Motivos detalle'!$H:$H,$J8))} -> 18.64 | N8: {=IF($J8="","Abierto",INDEX('Motivos detalle'!$D:$D,$J8))} -> ruptura piso Donchian | O8: {=IF($J8="","",INDEX('Motivos detalle'!$E:$E,$J8))} -> 1 | P8: =IF(J8="","",K8-D8) -> 63 | Q8: =IF(J8="","",L8/G8-1) -> 0.020994475 | R8: =IF(J8="","Abierto",IF(Q8>0,"Ganador","Perdedor")) -> Ganador | S8: =VLOOKUP(F8,Parametros!$A$25:$B$29,2,TRUE) -> 15% a 30% | T8: =IF(ISNUMBER(SEARCH("piso",N8)),L8/M8-1,"") -> -0.008583691 | U8: {=IF(J8="","",IFERROR(_xlfn.AGGREGATE(15,6,ROW('Motivos detalle'!$C$2:$C$274)/(('Motivos detalle'!$C$2:$C$274="ENTRA")*('Motivos detalle'!$B$2:$B$274=C8)*(ROW('Motivos detalle'!$C$2:$C$274)>J8)),1),""))} -> 16 | V8: {=IF(U8="","",INDEX('Motivos detalle'!$A:$A,U8))} -> 42634 | W8: =IF(V8="","",V8-K8) -> 47 | X8: {=IF(U8="","",INDEX('Motivos detalle'!$G:$G,U8))} -> 18.62 | Y8: =IF(W8="","No",IF(W8<Parametros!$B$4,"Sí","No")) -> No | Z8: =IF(Y8="Sí",X8/L8-1,"") | AA8: =IF(F8>Parametros!$B$7,"Sí","No") -> Sí | AB8: =VLOOKUP(YEAR(D8),Parametros!$A$11:$B$21,2,FALSE) -> 0.003 | AC8: =IF(F8>AB8,"Sí","No") -> Sí | AD8: =IF(N8="ruptura piso Donchian",IF(T8>-Parametros!$B$6,"Sí","No"),"") -> No | AE8: =IF(J8="","",(L8*(1-Parametros!$B$32))/(G8*(1+Parametros!$B$32))-1) -> 0.016918649 | AF8: =IF(J8="","",Q8-AE8) -> 0.0040758262
A9: =ROW()-3 -> 6 | B9: {=IFERROR(_xlfn.AGGREGATE(15,6,ROW('Motivos detalle'!$C$2:$C$274)/('Motivos detalle'!$C$2:$C$274="ENTRA"),A9),"")} -> 10 | C9: {=INDEX('Motivos detalle'!$B:$B,$B9)} -> XLK | D9: {=INDEX('Motivos detalle'!$A:$A,$B9)} -> 42562 | E9: {=INDEX('Motivos detalle'!$E:$E,$B9)} -> 3 | F9: {=INDEX('Motivos detalle'!$F:$F,$B9)} -> 0.0922 | G9: {=INDEX('Motivos detalle'!$G:$G,$B9)} -> 19.98 | H9: {=INDEX('Motivos detalle'!$H:$H,$B9)} -> 19.88 | I9: =G9/H9-1 -> 0.0050301811 | J9: {=IFERROR(_xlfn.AGGREGATE(15,6,ROW('Motivos detalle'!$C$2:$C$274)/(('Motivos detalle'!$C$2:$C$274="SALE")*('Motivos detalle'!$B$2:$B$274=C9)*(ROW('Motivos detalle'!$C$2:$C$274)>B9)),1),"")} -> 14 | K9: {=IF($J9="","",INDEX('Motivos detalle'!$A:$A,$J9))} -> 42622 | L9: {=IF($J9="","",INDEX('Motivos detalle'!$G:$G,$J9))} -> 20.78 | M9: {=IF($J9="","",INDEX('Motivos detalle'!$H:$H,$J9))} -> 21.02 | N9: {=IF($J9="","Abierto",INDEX('Motivos detalle'!$D:$D,$J9))} -> ruptura piso Donchian | O9: {=IF($J9="","",INDEX('Motivos detalle'!$E:$E,$J9))} -> 2 | P9: =IF(J9="","",K9-D9) -> 60 | Q9: =IF(J9="","",L9/G9-1) -> 0.04004004 | R9: =IF(J9="","Abierto",IF(Q9>0,"Ganador","Perdedor")) -> Ganador | S9: =VLOOKUP(F9,Parametros!$A$25:$B$29,2,TRUE) -> 5% a 15% | T9: =IF(ISNUMBER(SEARCH("piso",N9)),L9/M9-1,"") -> -0.011417697 | U9: {=IF(J9="","",IFERROR(_xlfn.AGGREGATE(15,6,ROW('Motivos detalle'!$C$2:$C$274)/(('Motivos detalle'!$C$2:$C$274="ENTRA")*('Motivos detalle'!$B$2:$B$274=C9)*(ROW('Motivos detalle'!$C$2:$C$274)>J9)),1),""))} -> 17 | V9: {=IF(U9="","",INDEX('Motivos detalle'!$A:$A,U9))} -> 42635 | W9: =IF(V9="","",V9-K9) -> 13 | X9: {=IF(U9="","",INDEX('Motivos detalle'!$G:$G,U9))} -> 21.65 | Y9: =IF(W9="","No",IF(W9<Parametros!$B$4,"Sí","No")) -> No | Z9: =IF(Y9="Sí",X9/L9-1,"") | AA9: =IF(F9>Parametros!$B$7,"Sí","No") -> Sí | AB9: =VLOOKUP(YEAR(D9),Parametros!$A$11:$B$21,2,FALSE) -> 0.003 | AC9: =IF(F9>AB9,"Sí","No") -> Sí | AD9: =IF(N9="ruptura piso Donchian",IF(T9>-Parametros!$B$6,"Sí","No"),"") -> No | AE9: =IF(J9="","",(L9*(1-Parametros!$B$32))/(G9*(1+Parametros!$B$32))-1) -> 0.035888184 | AF9: =IF(J9="","",Q9-AE9) -> 0.0041518564
A10: =ROW()-3 -> 7 | B10: {=IFERROR(_xlfn.AGGREGATE(15,6,ROW('Motivos detalle'!$C$2:$C$274)/('Motivos detalle'!$C$2:$C$274="ENTRA"),A10),"")} -> 12 | C10: {=INDEX('Motivos detalle'!$B:$B,$B10)} -> XLB | D10: {=INDEX('Motivos detalle'!$A:$A,$B10)} -> 42605 | E10: {=INDEX('Motivos detalle'!$E:$E,$B10)} -> 3 | F10: {=INDEX('Motivos detalle'!$F:$F,$B10)} -> 0.2182 | G10: {=INDEX('Motivos detalle'!$G:$G,$B10)} -> 20.2 | H10: {=INDEX('Motivos detalle'!$H:$H,$B10)} -> 20.14 | I10: =G10/H10-1 -> 0.002979146 | J10: {=IFERROR(_xlfn.AGGREGATE(15,6,ROW('Motivos detalle'!$C$2:$C$274)/(('Motivos detalle'!$C$2:$C$274="SALE")*('Motivos detalle'!$B$2:$B$274=C10)*(ROW('Motivos detalle'!$C$2:$C$274)>B10)),1),"")} -> 15 | K10: {=IF($J10="","",INDEX('Motivos detalle'!$A:$A,$J10))} -> 42622 | L10: {=IF($J10="","",INDEX('Motivos detalle'!$G:$G,$J10))} -> 19.43 | M10: {=IF($J10="","",INDEX('Motivos detalle'!$H:$H,$J10))} -> 19.74 | N10: {=IF($J10="","Abierto",INDEX('Motivos detalle'!$D:$D,$J10))} -> ruptura piso Donchian | O10: {=IF($J10="","",INDEX('Motivos detalle'!$E:$E,$J10))} -> 5 | P10: =IF(J10="","",K10-D10) -> 17 | Q10: =IF(J10="","",L10/G10-1) -> -0.038118812 | R10: =IF(J10="","Abierto",IF(Q10>0,"Ganador","Perdedor")) -> Perdedor | S10: =VLOOKUP(F10,Parametros!$A$25:$B$29,2,TRUE) -> 15% a 30% | T10: =IF(ISNUMBER(SEARCH("piso",N10)),L10/M10-1,"") -> -0.015704154 | U10: {=IF(J10="","",IFERROR(_xlfn.AGGREGATE(15,6,ROW('Motivos detalle'!$C$2:$C$274)/(('Motivos detalle'!$C$2:$C$274="ENTRA")*('Motivos detalle'!$B$2:$B$274=C10)*(ROW('Motivos detalle'!$C$2:$C$274)>J10)),1),""))} -> 23 | V10: {=IF(U10="","",INDEX('Motivos detalle'!$A:$A,U10))} -> 42684 | W10: =IF(V10="","",V10-K10) -> 62 | X10: {=IF(U10="","",INDEX('Motivos detalle'!$G:$G,U10))} -> 20.09 | Y10: =IF(W10="","No",IF(W10<Parametros!$B$4,"Sí","No")) -> No | Z10: =IF(Y10="Sí",X10/L10-1,"") | AA10: =IF(F10>Parametros!$B$7,"Sí","No") -> Sí | AB10: =VLOOKUP(YEAR(D10),Parametros!$A$11:$B$21,2,FALSE) -> 0.003 | AC10: =IF(F10>AB10,"Sí","No") -> Sí | AD10: =IF(N10="ruptura piso Donchian",IF(T10>-Parametros!$B$6,"Sí","No"),"") -> No | AE10: =IF(J10="","",(L10*(1-Parametros!$B$32))/(G10*(1+Parametros!$B$32))-1) -> -0.041958657 | AF10: =IF(J10="","",Q10-AE10) -> 0.0038398451
A11: =ROW()-3 -> 8 | B11: {=IFERROR(_xlfn.AGGREGATE(15,6,ROW('Motivos detalle'!$C$2:$C$274)/('Motivos detalle'!$C$2:$C$274="ENTRA"),A11),"")} -> 16 | C11: {=INDEX('Motivos detalle'!$B:$B,$B11)} -> XLU | D11: {=INDEX('Motivos detalle'!$A:$A,$B11)} -> 42634 | E11: {=INDEX('Motivos detalle'!$E:$E,$B11)} -> 1 | F11: {=INDEX('Motivos detalle'!$F:$F,$B11)} -> 0.2525 | G11: {=INDEX('Motivos detalle'!$G:$G,$B11)} -> 18.62 | H11: {=INDEX('Motivos detalle'!$H:$H,$B11)} -> 18.48 | I11: =G11/H11-1 -> 0.0075757576 | J11: {=IFERROR(_xlfn.AGGREGATE(15,6,ROW('Motivos detalle'!$C$2:$C$274)/(('Motivos detalle'!$C$2:$C$274="SALE")*('Motivos detalle'!$B$2:$B$274=C11)*(ROW('Motivos detalle'!$C$2:$C$274)>B11)),1),"")} -> 18 | K11: {=IF($J11="","",INDEX('Motivos detalle'!$A:$A,$J11))} -> 42647 | L11: {=IF($J11="","",INDEX('Motivos detalle'!$G:$G,$J11))} -> 17.38 | M11: {=IF($J11="","",INDEX('Motivos detalle'!$H:$H,$J11))} -> 17.63 | N11: {=IF($J11="","Abierto",INDEX('Motivos detalle'!$D:$D,$J11))} -> ruptura piso Donchian | O11: {=IF($J11="","",INDEX('Motivos detalle'!$E:$E,$J11))} -> 4 | P11: =IF(J11="","",K11-D11) -> 13 | Q11: =IF(J11="","",L11/G11-1) -> -0.066595059 | R11: =IF(J11="","Abierto",IF(Q11>0,"Ganador","Perdedor")) -> Perdedor | S11: =VLOOKUP(F11,Parametros!$A$25:$B$29,2,TRUE) -> 15% a 30% | T11: =IF(ISNUMBER(SEARCH("piso",N11)),L11/M11-1,"") -> -0.014180374 | U11: {=IF(J11="","",IFERROR(_xlfn.AGGREGATE(15,6,ROW('Motivos detalle'!$C$2:$C$274)/(('Motivos detalle'!$C$2:$C$274="ENTRA")*('Motivos detalle'!$B$2:$B$274=C11)*(ROW('Motivos detalle'!$C$2:$C$274)>J11)),1),""))} -> 19 | V11: {=IF(U11="","",INDEX('Motivos detalle'!$A:$A,U11))} -> 42674 | W11: =IF(V11="","",V11-K11) -> 27 | X11: {=IF(U11="","",INDEX('Motivos detalle'!$G:$G,U11))} -> 18.16 | Y11: =IF(W11="","No",IF(W11<Parametros!$B$4,"Sí","No")) -> No | Z11: =IF(Y11="Sí",X11/L11-1,"") | AA11: =IF(F11>Parametros!$B$7,"Sí","No") -> Sí | AB11: =VLOOKUP(YEAR(D11),Parametros!$A$11:$B$21,2,FALSE) -> 0.003 | AC11: =IF(F11>AB11,"Sí","No") -> Sí | AD11: =IF(N11="ruptura piso Donchian",IF(T11>-Parametros!$B$6,"Sí","No"),"") -> No | AE11: =IF(J11="","",(L11*(1-Parametros!$B$32))/(G11*(1+Parametros!$B$32))-1) -> -0.070321227 | AF11: =IF(J11="","",Q11-AE11) -> 0.0037261674
A12: =ROW()-3 -> 9 | B12: {=IFERROR(_xlfn.AGGREGATE(15,6,ROW('Motivos detalle'!$C$2:$C$274)/('Motivos detalle'!$C$2:$C$274="ENTRA"),A12),"")} -> 17 | C12: {=INDEX('Motivos detalle'!$B:$B,$B12)} -> XLK | D12: {=INDEX('Motivos detalle'!$A:$A,$B12)} -> 42635 | E12: {=INDEX('Motivos detalle'!$E:$E,$B12)} -> 2 | F12: {=INDEX('Motivos detalle'!$F:$F,$B12)} -> 0.2244 | G12: {=INDEX('Motivos detalle'!$G:$G,$B12)} -> 21.65 | H12: {=INDEX('Motivos detalle'!$H:$H,$B12)} -> 21.54 | I12: =G12/H12-1 -> 0.0051067781 | J12: {=IFERROR(_xlfn.AGGREGATE(15,6,ROW('Motivos detalle'!$C$2:$C$274)/(('Motivos detalle'!$C$2:$C$274="SALE")*('Motivos detalle'!$B$2:$B$274=C12)*(ROW('Motivos detalle'!$C$2:$C$274)>B12)),1),"")} -> 20 | K12: {=IF($J12="","",INDEX('Motivos detalle'!$A:$A,$J12))} -> 42677 | L12: {=IF($J12="","",INDEX('Motivos detalle'!$G:$G,$J12))} -> 20.91 | M12: {=IF($J12="","",INDEX('Motivos detalle'!$H:$H,$J12))} -> 21.06 | N12: {=IF($J12="","Abierto",INDEX('Motivos detalle'!$D:$D,$J12))} -> ruptura piso Donchian | O12: {=IF($J12="","",INDEX('Motivos detalle'!$E:$E,$J12))} -> 3 | P12: =IF(J12="","",K12-D12) -> 42 | Q12: =IF(J12="","",L12/G12-1) -> -0.034180139 | R12: =IF(J12="","Abierto",IF(Q12>0,"Ganador","Perdedor")) -> Perdedor | S12: =VLOOKUP(F12,Parametros!$A$25:$B$29,2,TRUE) -> 15% a 30% | T12: =IF(ISNUMBER(SEARCH("piso",N12)),L12/M12-1,"") -> -0.0071225071 | U12: {=IF(J12="","",IFERROR(_xlfn.AGGREGATE(15,6,ROW('Motivos detalle'!$C$2:$C$274)/(('Motivos detalle'!$C$2:$C$274="ENTRA")*('Motivos detalle'!$B$2:$B$274=C12)*(ROW('Motivos detalle'!$C$2:$C$274)>J12)),1),""))} -> 36 | V12: {=IF(U12="","",INDEX('Motivos detalle'!$A:$A,U12))} -> 42850 | W12: =IF(V12="","",V12-K12) -> 173 | X12: {=IF(U12="","",INDEX('Motivos detalle'!$G:$G,U12))} -> 24.64 | Y12: =IF(W12="","No",IF(W12<Parametros!$B$4,"Sí","No")) -> No | Z12: =IF(Y12="Sí",X12/L12-1,"") | AA12: =IF(F12>Parametros!$B$7,"Sí","No") -> Sí | AB12: =VLOOKUP(YEAR(D12),Parametros!$A$11:$B$21,2,FALSE) -> 0.003 | AC12: =IF(F12>AB12,"Sí","No") -> Sí | AD12: =IF(N12="ruptura piso Donchian",IF(T12>-Parametros!$B$6,"Sí","No"),"") -> No | AE12: =IF(J12="","",(L12*(1-Parametros!$B$32))/(G12*(1+Parametros!$B$32))-1) -> -0.038035707 | AF12: =IF(J12="","",Q12-AE12) -> 0.0038555683
A13: =ROW()-3 -> 10 | B13: {=IFERROR(_xlfn.AGGREGATE(15,6,ROW('Motivos detalle'!$C$2:$C$274)/('Motivos detalle'!$C$2:$C$274="ENTRA"),A13),"")} -> 19 | C13: {=INDEX('Motivos detalle'!$B:$B,$B13)} -> XLU | D13: {=INDEX('Motivos detalle'!$A:$A,$B13)} -> 42674 | E13: {=INDEX('Motivos detalle'!$E:$E,$B13)} -> 1 | F13: {=INDEX('Motivos detalle'!$F:$F,$B13)} -> 0.1694 | G13: {=INDEX('Motivos detalle'!$G:$G,$B13)} -> 18.16 | H13: {=INDEX('Motivos detalle'!$H:$H,$B13)} -> 18.01 | I13: =G13/H13-1 -> 0.0083287063 | J13: {=IFERROR(_xlfn.AGGREGATE(15,6,ROW('Motivos detalle'!$C$2:$C$274)/(('Motivos detalle'!$C$2:$C$274="SALE")*('Motivos detalle'!$B$2:$B$274=C13)*(ROW('Motivos detalle'!$C$2:$C$274)>B13)),1),"")} -> 22 | K13: {=IF($J13="","",INDEX('Motivos detalle'!$A:$A,$J13))} -> 42684 | L13: {=IF($J13="","",INDEX('Motivos detalle'!$G:$G,$J13))} -> 16.99 | M13: {=IF($J13="","",INDEX('Motivos detalle'!$H:$H,$J13))} -> 17.37 | N13: {=IF($J13="","Abierto",INDEX('Motivos detalle'!$D:$D,$J13))} -> ruptura piso Donchian | O13: {=IF($J13="","",INDEX('Motivos detalle'!$E:$E,$J13))} -> 3 | P13: =IF(J13="","",K13-D13) -> 10 | Q13: =IF(J13="","",L13/G13-1) -> -0.064427313 | R13: =IF(J13="","Abierto",IF(Q13>0,"Ganador","Perdedor")) -> Perdedor | S13: =VLOOKUP(F13,Parametros!$A$25:$B$29,2,TRUE) -> 15% a 30% | T13: =IF(ISNUMBER(SEARCH("piso",N13)),L13/M13-1,"") -> -0.021876799 | U13: {=IF(J13="","",IFERROR(_xlfn.AGGREGATE(15,6,ROW('Motivos detalle'!$C$2:$C$274)/(('Motivos detalle'!$C$2:$C$274="ENTRA")*('Motivos detalle'!$B$2:$B$274=C13)*(ROW('Motivos detalle'!$C$2:$C$274)>J13)),1),""))} -> 44 | V13: {=IF(U13="","",INDEX('Motivos detalle'!$A:$A,U13))} -> 43052 | W13: =IF(V13="","",V13-K13) -> 368 | X13: {=IF(U13="","",INDEX('Motivos detalle'!$G:$G,U13))} -> 21.33 | Y13: =IF(W13="","No",IF(W13<Parametros!$B$4,"Sí","No")) -> No | Z13: =IF(Y13="Sí",X13/L13-1,"") | AA13: =IF(F13>Parametros!$B$7,"Sí","No") -> Sí | AB13: =VLOOKUP(YEAR(D13),Parametros!$A$11:$B$21,2,FALSE) -> 0.003 | AC13: =IF(F13>AB13,"Sí","No") -> Sí | AD13: =IF(N13="ruptura piso Donchian",IF(T13>-Parametros!$B$6,"Sí","No"),"") -> No | AE13: =IF(J13="","",(L13*(1-Parametros!$B$32))/(G13*(1+Parametros!$B$32))-1) -> -0.068162134 | AF13: =IF(J13="","",Q13-AE13) -> 0.0037348211
A14: =ROW()-3 -> 11 | B14: {=IFERROR(_xlfn.AGGREGATE(15,6,ROW('Motivos detalle'!$C$2:$C$274)/('Motivos detalle'!$C$2:$C$274="ENTRA"),A14),"")} -> 21 | C14: {=INDEX('Motivos detalle'!$B:$B,$B14)} -> XLI | D14: {=INDEX('Motivos detalle'!$A:$A,$B14)} -> 42683 | E14: {=INDEX('Motivos detalle'!$E:$E,$B14)} -> 2 | F14: {=INDEX('Motivos detalle'!$F:$F,$B14)} -> 0.1208 | G14: {=INDEX('Motivos detalle'!$G:$G,$B14)} -> 50.51 | H14: {=INDEX('Motivos detalle'!$H:$H,$B14)} -> 49.43 | I14: =G14/H14-1 -> 0.02184908 | J14: {=IFERROR(_xlfn.AGGREGATE(15,6,ROW('Motivos detalle'!$C$2:$C$274)/(('Motivos detalle'!$C$2:$C$274="SALE")*('Motivos detalle'!$B$2:$B$274=C14)*(ROW('Motivos detalle'!$C$2:$C$274)>B14)),1),"")} -> 33 | K14: {=IF($J14="","",INDEX('Motivos detalle'!$A:$A,$J14))} -> 42815 | L14: {=IF($J14="","",INDEX('Motivos detalle'!$G:$G,$J14))} -> 55.24 | M14: {=IF($J14="","",INDEX('Motivos detalle'!$H:$H,$J14))} -> 55.4 | N14: {=IF($J14="","Abierto",INDEX('Motivos detalle'!$D:$D,$J14))} -> ruptura piso Donchian | O14: {=IF($J14="","",INDEX('Motivos detalle'!$E:$E,$J14))} -> 3 | P14: =IF(J14="","",K14-D14) -> 132 | Q14: =IF(J14="","",L14/G14-1) -> 0.093644823 | R14: =IF(J14="","Abierto",IF(Q14>0,"Ganador","Perdedor")) -> Ganador | S14: =VLOOKUP(F14,Parametros!$A$25:$B$29,2,TRUE) -> 5% a 15% | T14: =IF(ISNUMBER(SEARCH("piso",N14)),L14/M14-1,"") -> -0.0028880866 | U14: {=IF(J14="","",IFERROR(_xlfn.AGGREGATE(15,6,ROW('Motivos detalle'!$C$2:$C$274)/(('Motivos detalle'!$C$2:$C$274="ENTRA")*('Motivos detalle'!$B$2:$B$274=C14)*(ROW('Motivos detalle'!$C$2:$C$274)>J14)),1),""))} -> 35 | V14: {=IF(U14="","",INDEX('Motivos detalle'!$A:$A,U14))} -> 42849 | W14: =IF(V14="","",V14-K14) -> 34 | X14: {=IF(U14="","",INDEX('Motivos detalle'!$G:$G,U14))} -> 56.76 | Y14: =IF(W14="","No",IF(W14<Parametros!$B$4,"Sí","No")) -> No | Z14: =IF(Y14="Sí",X14/L14-1,"") | AA14: =IF(F14>Parametros!$B$7,"Sí","No") -> Sí | AB14: =VLOOKUP(YEAR(D14),Parametros!$A$11:$B$21,2,FALSE) -> 0.003 | AC14: =IF(F14>AB14,"Sí","No") -> Sí | AD14: =IF(N14="ruptura piso Donchian",IF(T14>-Parametros!$B$6,"Sí","No"),"") -> Sí | AE14: =IF(J14="","",(L14*(1-Parametros!$B$32))/(G14*(1+Parametros!$B$32))-1) -> 0.089278975 | AF14: =IF(J14="","",Q14-AE14) -> 0.0043658476
A15: =ROW()-3 -> 12 | B15: {=IFERROR(_xlfn.AGGREGATE(15,6,ROW('Motivos detalle'!$C$2:$C$274)/('Motivos detalle'!$C$2:$C$274="ENTRA"),A15),"")} -> 23 | C15: {=INDEX('Motivos detalle'!$B:$B,$B15)} -> XLB | D15: {=INDEX('Motivos detalle'!$A:$A,$B15)} -> 42684 | E15: {=INDEX('Motivos detalle'!$E:$E,$B15)} -> 2 | F15: {=INDEX('Motivos detalle'!$F:$F,$B15)} -> 0.1144 | G15: {=INDEX('Motivos detalle'!$G:$G,$B15)} -> 20.09 | H15: {=INDEX('Motivos detalle'!$H:$H,$B15)} -> 19.91 | I15: =G15/H15-1 -> 0.0090406831 | J15: {=IFERROR(_xlfn.AGGREGATE(15,6,ROW('Motivos detalle'!$C$2:$C$274)/(('Motivos detalle'!$C$2:$C$274="SALE")*('Motivos detalle'!$B$2:$B$274=C15)*(ROW('Motivos detalle'!$C$2:$C$274)>B15)),1),"")} -> 25 | K15: {=IF($J15="","",INDEX('Motivos detalle'!$A:$A,$J15))} -> 42692 | L15: {=IF($J15="","",INDEX('Motivos detalle'!$G:$G,$J15))} -> 19.89 | M15: {=IF($J15="","",INDEX('Motivos detalle'!$H:$H,$J15))} -> 18.98 | N15: {=IF($J15="","Abierto",INDEX('Motivos detalle'!$D:$D,$J15))} -> cae del ranking (>#5) | O15: {=IF($J15="","",INDEX('Motivos detalle'!$E:$E,$J15))} -> 6 | P15: =IF(J15="","",K15-D15) -> 8 | Q15: =IF(J15="","",L15/G15-1) -> -0.0099552016 | R15: =IF(J15="","Abierto",IF(Q15>0,"Ganador","Perdedor")) -> Perdedor | S15: =VLOOKUP(F15,Parametros!$A$25:$B$29,2,TRUE) -> 5% a 15% | T15: =IF(ISNUMBER(SEARCH("piso",N15)),L15/M15-1,"") | U15: {=IF(J15="","",IFERROR(_xlfn.AGGREGATE(15,6,ROW('Motivos detalle'!$C$2:$C$274)/(('Motivos detalle'!$C$2:$C$274="ENTRA")*('Motivos detalle'!$B$2:$B$274=C15)*(ROW('Motivos detalle'!$C$2:$C$274)>J15)),1),""))} -> 31 | V15: {=IF(U15="","",INDEX('Motivos detalle'!$A:$A,U15))} -> 42759 | W15: =IF(V15="","",V15-K15) -> 67 | X15: {=IF(U15="","",INDEX('Motivos detalle'!$G:$G,U15))} -> 21.76 | Y15: =IF(W15="","No",IF(W15<Parametros!$B$4,"Sí","No")) -> No | Z15: =IF(Y15="Sí",X15/L15-1,"") | AA15: =IF(F15>Parametros!$B$7,"Sí","No") -> Sí | AB15: =VLOOKUP(YEAR(D15),Parametros!$A$11:$B$21,2,FALSE) -> 0.003 | AC15: =IF(F15>AB15,"Sí","No") -> Sí | AD15: =IF(N15="ruptura piso Donchian",IF(T15>-Parametros!$B$6,"Sí","No"),"") | AE15: =IF(J15="","",(L15*(1-Parametros!$B$32))/(G15*(1+Parametros!$B$32))-1) -> -0.013907476 | AF15: =IF(J15="","",Q15-AE15) -> 0.0039522746
... A140: =ROW()-3 -> 137 | B140: {=IFERROR(_xlfn.AGGREGATE(15,6,ROW('Motivos detalle'!$C$2:$C$274)/('Motivos detalle'!$C$2:$C$274="ENTRA"),A140),"")} -> 272 | C140: {=INDEX('Motivos detalle'!$B:$B,$B140)} -> XLI | D140: {=INDEX('Motivos detalle'!$A:$A,$B140)} -> 46238 | E140: {=INDEX('Motivos detalle'!$E:$E,$B140)} -> 3 | F140: {=INDEX('Motivos detalle'!$F:$F,$B140)} -> 0.2609 | G140: {=INDEX('Motivos detalle'!$G:$G,$B140)} -> 186.4 | H140: {=INDEX('Motivos detalle'!$H:$H,$B140)} -> 184.92 | I140: =G140/H140-1 -> 0.008003461 | J140: {=IFERROR(_xlfn.AGGREGATE(15,6,ROW('Motivos detalle'!$C$2:$C$274)/(('Motivos detalle'!$C$2:$C$274="SALE")*('Motivos detalle'!$B$2:$B$274=C140)*(ROW('Motivos detalle'!$C$2:$C$274)>B140)),1),"")} -> 273 | K140: {=IF($J140="","",INDEX('Motivos detalle'!$A:$A,$J140))} -> 46262 | L140: {=IF($J140="","",INDEX('Motivos detalle'!$G:$G,$J140))} -> 177.14 | M140: {=IF($J140="","",INDEX('Motivos detalle'!$H:$H,$J140))} -> 177.89 | N140: {=IF($J140="","Abierto",INDEX('Motivos detalle'!$D:$D,$J140))} -> ruptura piso Donchian | O140: {=IF($J140="","",INDEX('Motivos detalle'!$E:$E,$J140))} -> 5 | P140: =IF(J140="","",K140-D140) -> 24 | Q140: =IF(J140="","",L140/G140-1) -> -0.049678112 | R140: =IF(J140="","Abierto",IF(Q140>0,"Ganador","Perdedor")) -> Perdedor | S140: =VLOOKUP(F140,Parametros!$A$25:$B$29,2,TRUE) -> 15% a 30% | T140: =IF(ISNUMBER(SEARCH("piso",N140)),L140/M140-1,"") -> -0.0042160886 | U140: {=IF(J140="","",IFERROR(_xlfn.AGGREGATE(15,6,ROW('Motivos detalle'!$C$2:$C$274)/(('Motivos detalle'!$C$2:$C$274="ENTRA")*('Motivos detalle'!$B$2:$B$274=C140)*(ROW('Motivos detalle'!$C$2:$C$274)>J140)),1),""))} | V140: {=IF(U140="","",INDEX('Motivos detalle'!$A:$A,U140))} | W140: =IF(V140="","",V140-K140) | X140: {=IF(U140="","",INDEX('Motivos detalle'!$G:$G,U140))} | Y140: =IF(W140="","No",IF(W140<Parametros!$B$4,"Sí","No")) -> No | Z140: =IF(Y140="Sí",X140/L140-1,"") | AA140: =IF(F140>Parametros!$B$7,"Sí","No") -> Sí | AB140: =VLOOKUP(YEAR(D140),Parametros!$A$11:$B$21,2,FALSE) -> 0.037 | AC140: =IF(F140>AB140,"Sí","No") -> Sí | AD140: =IF(N140="ruptura piso Donchian",IF(T140>-Parametros!$B$6,"Sí","No"),"") -> No | AE140: =IF(J140="","",(L140*(1-Parametros!$B$32))/(G140*(1+Parametros!$B$32))-1) -> -0.053471812 | AF140: =IF(J140="","",Q140-AE140) -> 0.0037937002

Sheet Estadisticas
A1: Estadísticas de trades cerrados
A2: Solo trades cerrados (excluye el abierto). Retorno acumulado = suma simple de retornos por trade.
A4: Total | B4: Trades | C4: Ganadores | D4: % Ganadores | E4: Retorno promedio | F4: Retorno acumulado | G4: Días promedio | H4: Mejor trade | I4: Peor trade
A5: Todos | B5: =COUNTIFS(Trades!$R$4:$R$140,"<>Abierto") -> 136 | C5: =COUNTIFS(Trades!$R$4:$R$140,"Ganador") -> 67 | D5: =IFERROR(C5/B5,0) -> 0.49264706 | E5: =IFERROR(AVERAGEIFS(Trades!$Q$4:$Q$140,Trades!$R$4:$R$140,"<>Abierto"),0) -> 0.0096218743 | F5: =SUMIFS(Trades!$Q$4:$Q$140,Trades!$R$4:$R$140,"<>Abierto") -> 1.3085749 | G5: =IFERROR(AVERAGEIFS(Trades!$P$4:$P$140,Trades!$R$4:$R$140,"<>Abierto"),0) -> 56.566176 | H5: =IF(B5=0,0,_xlfn.MAXIFS(Trades!$Q$4:$Q$140,Trades!$R$4:$R$140,"<>Abierto")) -> 0.25961765 | I5: =IF(B5=0,0,_xlfn.MINIFS(Trades!$Q$4:$Q$140,Trades!$R$4:$R$140,"<>Abierto")) -> -0.098686828
A7: Por activo | B7: Trades | C7: Ganadores | D7: % Ganadores | E7: Retorno promedio | F7: Retorno acumulado | G7: Días promedio | H7: Mejor trade | I7: Peor trade
A8: XLB | B8: =COUNTIFS(Trades!$C$4:$C$140,$A8,Trades!$R$4:$R$140,"<>Abierto") -> 8 | C8: =COUNTIFS(Trades!$C$4:$C$140,$A8,Trades!$R$4:$R$140,"Ganador") -> 4 | D8: =IFERROR(C8/B8,0) -> 0.5 | E8: =IFERROR(AVERAGEIFS(Trades!$Q$4:$Q$140,Trades!$C$4:$C$140,$A8,Trades!$R$4:$R$140,"<>Abierto"),0) -> -0.0025241671 | F8: =SUMIFS(Trades!$Q$4:$Q$140,Trades!$C$4:$C$140,$A8,Trades!$R$4:$R$140,"<>Abierto") -> -0.020193337 | G8: =IFERROR(AVERAGEIFS(Trades!$P$4:$P$140,Trades!$C$4:$C$140,$A8,Trades!$R$4:$R$140,"<>Abierto"),0) -> 39.125 | H8: =IF(B8=0,0,_xlfn.MAXIFS(Trades!$Q$4:$Q$140,Trades!$C$4:$C$140,$A8,Trades!$R$4:$R$140,"<>Abierto")) -> 0.094151213 | I8: =IF(B8=0,0,_xlfn.MINIFS(Trades!$Q$4:$Q$140,Trades!$C$4:$C$140,$A8,Trades!$R$4:$R$140,"<>Abierto")) -> -0.07013915
A9: XLC | B9: =COUNTIFS(Trades!$C$4:$C$140,$A9,Trades!$R$4:$R$140,"<>Abierto") -> 17 | C9: =COUNTIFS(Trades!$C$4:$C$140,$A9,Trades!$R$4:$R$140,"Ganador") -> 12 | D9: =IFERROR(C9/B9,0) -> 0.70588235 | E9: =IFERROR(AVERAGEIFS(Trades!$Q$4:$Q$140,Trades!$C$4:$C$140,$A9,Trades!$R$4:$R$140,"<>Abierto"),0) -> 0.032466703 | F9: =SUMIFS(Trades!$Q$4:$Q$140,Trades!$C$4:$C$140,$A9,Trades!$R$4:$R$140,"<>Abierto") -> 0.55193395 | G9: =IFERROR(AVERAGEIFS(Trades!$P$4:$P$140,Trades!$C$4:$C$140,$A9,Trades!$R$4:$R$140,"<>Abierto"),0) -> 65.529412 | H9: =IF(B9=0,0,_xlfn.MAXIFS(Trades!$Q$4:$Q$140,Trades!$C$4:$C$140,$A9,Trades!$R$4:$R$140,"<>Abierto")) -> 0.16472182 | I9: =IF(B9=0,0,_xlfn.MINIFS(Trades!$Q$4:$Q$140,Trades!$C$4:$C$140,$A9,Trades!$R$4:$R$140,"<>Abierto")) -> -0.079010969
A10: XLE | B10: =COUNTIFS(Trades!$C$4:$C$140,$A10,Trades!$R$4:$R$140,"<>Abierto") -> 12 | C10: =COUNTIFS(Trades!$C$4:$C$140,$A10,Trades!$R$4:$R$140,"Ganador") -> 6 | D10: =IFERROR(C10/B10,0) -> 0.5 | E10: =IFERROR(AVERAGEIFS(Trades!$Q$4:$Q$140,Trades!$C$4:$C$140,$A10,Trades!$R$4:$R$140,"<>Abierto"),0) -> 0.012917549 | F10: =SUMIFS(Trades!$Q$4:$Q$140,Trades!$C$4:$C$140,$A10,Trades!$R$4:$R$140,"<>Abierto") -> 0.15501059 | G10: =IFERROR(AVERAGEIFS(Trades!$P$4:$P$140,Trades!$C$4:$C$140,$A10,Trades!$R$4:$R$140,"<>Abierto"),0) -> 54.333333 | H10: =IF(B10=0,0,_xlfn.MAXIFS(Trades!$Q$4:$Q$140,Trades!$C$4:$C$140,$A10,Trades!$R$4:$R$140,"<>Abierto")) -> 0.25652174 | I10: =IF(B10=0,0,_xlfn.MINIFS(Trades!$Q$4:$Q$140,Trades!$C$4:$C$140,$A10,Trades!$R$4:$R$140,"<>Abierto")) -> -0.091493715
A11: XLF | B11: =COUNTIFS(Trades!$C$4:$C$140,$A11,Trades!$R$4:$R$140,"<>Abierto") -> 14 | C11: =COUNTIFS(Trades!$C$4:$C$140,$A11,Trades!$R$4:$R$140,"Ganador") -> 8 | D11: =IFERROR(C11/B11,0) -> 0.57142857 | E11: =IFERROR(AVERAGEIFS(Trades!$Q$4:$Q$140,Trades!$C$4:$C$140,$A11,Trades!$R$4:$R$140,"<>Abierto"),0) -> 0.015560886 | F11: =SUMIFS(Trades!$Q$4:$Q$140,Trades!$C$4:$C$140,$A11,Trades!$R$4:$R$140,"<>Abierto") -> 0.2178524 | G11: =IFERROR(AVERAGEIFS(Trades!$P$4:$P$140,Trades!$C$4:$C$140,$A11,Trades!$R$4:$R$140,"<>Abierto"),0) -> 61.142857 | H11: =IF(B11=0,0,_xlfn.MAXIFS(Trades!$Q$4:$Q$140,Trades!$C$4:$C$140,$A11,Trades!$R$4:$R$140,"<>Abierto")) -> 0.12464722 | I11: =IF(B11=0,0,_xlfn.MINIFS(Trades!$Q$4:$Q$140,Trades!$C$4:$C$140,$A11,Trades!$R$4:$R$140,"<>Abierto")) -> -0.063804647
A12: XLI | B12: =COUNTIFS(Trades!$C$4:$C$140,$A12,Trades!$R$4:$R$140,"<>Abierto") -> 12 | C12: =COUNTIFS(Trades!$C$4:$C$140,$A12,Trades!$R$4:$R$140,"Ganador") -> 5 | D12: =IFERROR(C12/B12,0) -> 0.41666667 | E12: =IFERROR(AVERAGEIFS(Trades!$Q$4:$Q$140,Trades!$C$4:$C$140,$A12,Trades!$R$4:$R$140,"<>Abierto"),0) -> 0.005542827 | F12: =SUMIFS(Trades!$Q$4:$Q$140,Trades!$C$4:$C$140,$A12,Trades!$R$4:$R$140,"<>Abierto") -> 0.066513924 | G12: =IFERROR(AVERAGEIFS(Trades!$P$4:$P$140,Trades!$C$4:$C$140,$A12,Trades!$R$4:$R$140,"<>Abierto"),0) -> 55.916667 | H12: =IF(B12=0,0,_xlfn.MAXIFS(Trades!$Q$4:$Q$140,Trades!$C$4:$C$140,$A12,Trades!$R$4:$R$140,"<>Abierto")) -> 0.093644823 | I12: =IF(B12=0,0,_xlfn.MINIFS(Trades!$Q$4:$Q$140,Trades!$C$4:$C$140,$A12,Trades!$R$4:$R$140,"<>Abierto")) -> -0.054528651
A13: XLK | B13: =COUNTIFS(Trades!$C$4:$C$140,$A13,Trades!$R$4:$R$140,"<>Abierto") -> 23 | C13: =COUNTIFS(Trades!$C$4:$C$140,$A13,Trades!$R$4:$R$140,"Ganador") -> 11 | D13: =IFERROR(C13/B13,0) -> 0.47826087 | E13: =IFERROR(AVERAGEIFS(Trades!$Q$4:$Q$140,Trades!$C$4:$C$140,$A13,Trades!$R$4:$R$140,"<>Abierto"),0) -> 0.031944253 | F13: =SUMIFS(Trades!$Q$4:$Q$140,Trades!$C$4:$C$140,$A13,Trades!$R$4:$R$140,"<>Abierto") -> 0.73471782 | G13: =IFERROR(AVERAGEIFS(Trades!$P$4:$P$140,Trades!$C$4:$C$140,$A13,Trades!$R$4:$R$140,"<>Abierto"),0) -> 66.043478 | H13: =IF(B13=0,0,_xlfn.MAXIFS(Trades!$Q$4:$Q$140,Trades!$C$4:$C$140,$A13,Trades!$R$4:$R$140,"<>Abierto")) -> 0.25961765 | I13: =IF(B13=0,0,_xlfn.MINIFS(Trades!$Q$4:$Q$140,Trades!$C$4:$C$140,$A13,Trades!$R$4:$R$140,"<>Abierto")) -> -0.085538462
A14: XLP | B14: =COUNTIFS(Trades!$C$4:$C$140,$A14,Trades!$R$4:$R$140,"<>Abierto") -> 7 | C14: =COUNTIFS(Trades!$C$4:$C$140,$A14,Trades!$R$4:$R$140,"Ganador") -> 3 | D14: =IFERROR(C14/B14,0) -> 0.42857143 | E14: =IFERROR(AVERAGEIFS(Trades!$Q$4:$Q$140,Trades!$C$4:$C$140,$A14,Trades!$R$4:$R$140,"<>Abierto"),0) -> 0.0057796198 | F14: =SUMIFS(Trades!$Q$4:$Q$140,Trades!$C$4:$C$140,$A14,Trades!$R$4:$R$140,"<>Abierto") -> 0.040457338 | G14: =IFERROR(AVERAGEIFS(Trades!$P$4:$P$140,Trades!$C$4:$C$140,$A14,Trades!$R$4:$R$140,"<>Abierto"),0) -> 62.571429 | H14: =IF(B14=0,0,_xlfn.MAXIFS(Trades!$Q$4:$Q$140,Trades!$C$4:$C$140,$A14,Trades!$R$4:$R$140,"<>Abierto")) -> 0.055704498 | I14: =IF(B14=0,0,_xlfn.MINIFS(Trades!$Q$4:$Q$140,Trades!$C$4:$C$140,$A14,Trades!$R$4:$R$140,"<>Abierto")) -> -0.020014826
A15: XLRE | B15: =COUNTIFS(Trades!$C$4:$C$140,$A15,Trades!$R$4:$R$140,"<>Abierto") -> 6 | C15: =COUNTIFS(Trades!$C$4:$C$140,$A15,Trades!$R$4:$R$140,"Ganador") -> 2 | D15: =IFERROR(C15/B15,0) -> 0.33333333 | E15: =IFERROR(AVERAGEIFS(Trades!$Q$4:$Q$140,Trades!$C$4:$C$140,$A15,Trades!$R$4:$R$140,"<>Abierto"),0) -> 0.013537188 | F15: =SUMIFS(Trades!$Q$4:$Q$140,Trades!$C$4:$C$140,$A15,Trades!$R$4:$R$140,"<>Abierto") -> 0.081223128 | G15: =IFERROR(AVERAGEIFS(Trades!$P$4:$P$140,Trades!$C$4:$C$140,$A15,Trades!$R$4:$R$140,"<>Abierto"),0) -> 72 | H15: =IF(B15=0,0,_xlfn.MAXIFS(Trades!$Q$4:$Q$140,Trades!$C$4:$C$140,$A15,Trades!$R$4:$R$140,"<>Abierto")) -> 0.19512195 | I15: =IF(B15=0,0,_xlfn.MINIFS(Trades!$Q$4:$Q$140,Trades!$C$4:$C$140,$A15,Trades!$R$4:$R$140,"<>Abierto")) -> -0.063855715
A16: XLU | B16: =COUNTIFS(Trades!$C$4:$C$140,$A16,Trades!$R$4:$R$140,"<>Abierto") -> 15 | C16: =COUNTIFS(Trades!$C$4:$C$140,$A16,Trades!$R$4:$R$140,"Ganador") -> 7 | D16: =IFERROR(C16/B16,0) -> 0.46666667 | E16: =IFERROR(AVERAGEIFS(Trades!$Q$4:$Q$140,Trades!$C$4:$C$140,$A16,Trades!$R$4:$R$140,"<>Abierto"),0) -> -0.016566678 | F16: =SUMIFS(Trades!$Q$4:$Q$140,Trades!$C$4:$C$140,$A16,Trades!$R$4:$R$140,"<>Abierto") -> -0.24850016 | G16: =IFERROR(AVERAGEIFS(Trades!$P$4:$P$140,Trades!$C$4:$C$140,$A16,Trades!$R$4:$R$140,"<>Abierto"),0) -> 42.466667 | H16: =IF(B16=0,0,_xlfn.MAXIFS(Trades!$Q$4:$Q$140,Trades!$C$4:$C$140,$A16,Trades!$R$4:$R$140,"<>Abierto")) -> 0.061403509 | I16: =IF(B16=0,0,_xlfn.MINIFS(Trades!$Q$4:$Q$140,Trades!$C$4:$C$140,$A16,Trades!$R$4:$R$140,"<>Abierto")) -> -0.098686828
A17: XLV | B17: =COUNTIFS(Trades!$C$4:$C$140,$A17,Trades!$R$4:$R$140,"<>Abierto") -> 11 | C17: =COUNTIFS(Trades!$C$4:$C$140,$A17,Trades!$R$4:$R$140,"Ganador") -> 3 | D17: =IFERROR(C17/B17,0) -> 0.27272727 | E17: =IFERROR(AVERAGEIFS(Trades!$Q$4:$Q$140,Trades!$C$4:$C$140,$A17,Trades!$R$4:$R$140,"<>Abierto"),0) -> -0.022840547 | F17: =SUMIFS(Trades!$Q$4:$Q$140,Trades!$C$4:$C$140,$A17,Trades!$R$4:$R$140,"<>Abierto") -> -0.25124602 | G17: =IFERROR(AVERAGEIFS(Trades!$P$4:$P$140,Trades!$C$4:$C$140,$A17,Trades!$R$4:$R$140,"<>Abierto"),0) -> 41.818182 | H17: =IF(B17=0,0,_xlfn.MAXIFS(Trades!$Q$4:$Q$140,Trades!$C$4:$C$140,$A17,Trades!$R$4:$R$140,"<>Abierto")) -> 0.038537712 | I17: =IF(B17=0,0,_xlfn.MINIFS(Trades!$Q$4:$Q$140,Trades!$C$4:$C$140,$A17,Trades!$R$4:$R$140,"<>Abierto")) -> -0.092000961
A18: XLY | B18: =COUNTIFS(Trades!$C$4:$C$140,$A18,Trades!$R$4:$R$140,"<>Abierto") -> 11 | C18: =COUNTIFS(Trades!$C$4:$C$140,$A18,Trades!$R$4:$R$140,"Ganador") -> 6 | D18: =IFERROR(C18/B18,0) -> 0.54545455 | E18: =IFERROR(AVERAGEIFS(Trades!$Q$4:$Q$140,Trades!$C$4:$C$140,$A18,Trades!$R$4:$R$140,"<>Abierto"),0) -> -0.0017449744 | F18: =SUMIFS(Trades!$Q$4:$Q$140,Trades!$C$4:$C$140,$A18,Trades!$R$4:$R$140,"<>Abierto") -> -0.019194718 | G18: =IFERROR(AVERAGEIFS(Trades!$P$4:$P$140,Trades!$C$4:$C$140,$A18,Trades!$R$4:$R$140,"<>Abierto"),0) -> 54.636364 | H18: =IF(B18=0,0,_xlfn.MAXIFS(Trades!$Q$4:$Q$140,Trades!$C$4:$C$140,$A18,Trades!$R$4:$R$140,"<>Abierto")) -> 0.049500998 | I18: =IF(B18=0,0,_xlfn.MINIFS(Trades!$Q$4:$Q$140,Trades!$C$4:$C$140,$A18,Trades!$R$4:$R$140,"<>Abierto")) -> -0.07065125
A20: Por rank de entrada | B20: Trades | C20: Ganadores | D20: % Ganadores | E20: Retorno promedio | F20: Retorno acumulado | G20: Días promedio | H20: Mejor trade | I20: Peor trade
A21: 1 | B21: =COUNTIFS(Trades!$E$4:$E$140,$A21,Trades!$R$4:$R$140,"<>Abierto") -> 35 | C21: =COUNTIFS(Trades!$E$4:$E$140,$A21,Trades!$R$4:$R$140,"Ganador") -> 18 | D21: =IFERROR(C21/B21,0) -> 0.51428571 | E21: =IFERROR(AVERAGEIFS(Trades!$Q$4:$Q$140,Trades!$E$4:$E$140,$A21,Trades!$R$4:$R$140,"<>Abierto"),0) -> 0.028058931 | F21: =SUMIFS(Trades!$Q$4:$Q$140,Trades!$E$4:$E$140,$A21,Trades!$R$4:$R$140,"<>Abierto") -> 0.98206257 | G21: =IFERROR(AVERAGEIFS(Trades!$P$4:$P$140,Trades!$E$4:$E$140,$A21,Trades!$R$4:$R$140,"<>Abierto"),0) -> 66.2 | H21: =IF(B21=0,0,_xlfn.MAXIFS(Trades!$Q$4:$Q$140,Trades!$E$4:$E$140,$A21,Trades!$R$4:$R$140,"<>Abierto")) -> 0.25961765 | I21: =IF(B21=0,0,_xlfn.MINIFS(Trades!$Q$4:$Q$140,Trades!$E$4:$E$140,$A21,Trades!$R$4:$R$140,"<>Abierto")) -> -0.091493715
A22: 2 | B22: =COUNTIFS(Trades!$E$4:$E$140,$A22,Trades!$R$4:$R$140,"<>Abierto") -> 47 | C22: =COUNTIFS(Trades!$E$4:$E$140,$A22,Trades!$R$4:$R$140,"Ganador") -> 26 | D22: =IFERROR(C22/B22,0) -> 0.55319149 | E22: =IFERROR(AVERAGEIFS(Trades!$Q$4:$Q$140,Trades!$E$4:$E$140,$A22,Trades!$R$4:$R$140,"<>Abierto"),0) -> 0.014232629 | F22: =SUMIFS(Trades!$Q$4:$Q$140,Trades!$E$4:$E$140,$A22,Trades!$R$4:$R$140,"<>Abierto") -> 0.66893356 | G22: =IFERROR(AVERAGEIFS(Trades!$P$4:$P$140,Trades!$E$4:$E$140,$A22,Trades!$R$4:$R$140,"<>Abierto"),0) -> 64.978723 | H22: =IF(B22=0,0,_xlfn.MAXIFS(Trades!$Q$4:$Q$140,Trades!$E$4:$E$140,$A22,Trades!$R$4:$R$140,"<>Abierto")) -> 0.19512195 | I22: =IF(B22=0,0,_xlfn.MINIFS(Trades!$Q$4:$Q$140,Trades!$E$4:$E$140,$A22,Trades!$R$4:$R$140,"<>Abierto")) -> -0.098686828
A23: 3 | B23: =COUNTIFS(Trades!$E$4:$E$140,$A23,Trades!$R$4:$R$140,"<>Abierto") -> 54 | C23: =COUNTIFS(Trades!$E$4:$E$140,$A23,Trades!$R$4:$R$140,"Ganador") -> 23 | D23: =IFERROR(C23/B23,0) -> 0.42592593 | E23: =IFERROR(AVERAGEIFS(Trades!$Q$4:$Q$140,Trades!$E$4:$E$140,$A23,Trades!$R$4:$R$140,"<>Abierto"),0) -> -0.0063411336 | F23: =SUMIFS(Trades!$Q$4:$Q$140,Trades!$E$4:$E$140,$A23,Trades!$R$4:$R$140,"<>Abierto") -> -0.34242121 | G23: =IFERROR(AVERAGEIFS(Trades!$P$4:$P$140,Trades!$E$4:$E$140,$A23,Trades!$R$4:$R$140,"<>Abierto"),0) -> 43 | H23: =IF(B23=0,0,_xlfn.MAXIFS(Trades!$Q$4:$Q$140,Trades!$E$4:$E$140,$A23,Trades!$R$4:$R$140,"<>Abierto")) -> 0.074478989 | I23: =IF(B23=0,0,_xlfn.MINIFS(Trades!$Q$4:$Q$140,Trades!$E$4:$E$140,$A23,Trades!$R$4:$R$140,"<>Abierto")) -> -0.092000961
A25: Por motivo de salida | B25: Trades | C25: Ganadores | D25: % Ganadores | E25: Retorno promedio | F25: Retorno acumulado | G25: Días promedio | H25: Mejor trade | I25: Peor trade
A26: ruptura piso Donchian | B26: =COUNTIFS(Trades!$N$4:$N$140,$A26,Trades!$R$4:$R$140,"<>Abierto") -> 101 | C26: =COUNTIFS(Trades!$N$4:$N$140,$A26,Trades!$R$4:$R$140,"Ganador") -> 49 | D26: =IFERROR(C26/B26,0) -> 0.48514851 | E26: =IFERROR(AVERAGEIFS(Trades!$Q$4:$Q$140,Trades!$N$4:$N$140,$A26,Trades!$R$4:$R$140,"<>Abierto"),0) -> 0.010505734 | F26: =SUMIFS(Trades!$Q$4:$Q$140,Trades!$N$4:$N$140,$A26,Trades!$R$4:$R$140,"<>Abierto") -> 1.0610792 | G26: =IFERROR(AVERAGEIFS(Trades!$P$4:$P$140,Trades!$N$4:$N$140,$A26,Trades!$R$4:$R$140,"<>Abierto"),0) -> 65.257426 | H26: =IF(B26=0,0,_xlfn.MAXIFS(Trades!$Q$4:$Q$140,Trades!$N$4:$N$140,$A26,Trades!$R$4:$R$140,"<>Abierto")) -> 0.25961765 | I26: =IF(B26=0,0,_xlfn.MINIFS(Trades!$Q$4:$Q$140,Trades!$N$4:$N$140,$A26,Trades!$R$4:$R$140,"<>Abierto")) -> -0.098686828
A27: cae del ranking (>#5) | B27: =COUNTIFS(Trades!$N$4:$N$140,$A27,Trades!$R$4:$R$140,"<>Abierto") -> 33 | C27: =COUNTIFS(Trades!$N$4:$N$140,$A27,Trades!$R$4:$R$140,"Ganador") -> 18 | D27: =IFERROR(C27/B27,0) -> 0.54545455 | E27: =IFERROR(AVERAGEIFS(Trades!$Q$4:$Q$140,Trades!$N$4:$N$140,$A27,Trades!$R$4:$R$140,"<>Abierto"),0) -> 0.01010715 | F27: =SUMIFS(Trades!$Q$4:$Q$140,Trades!$N$4:$N$140,$A27,Trades!$R$4:$R$140,"<>Abierto") -> 0.33353595 | G27: =IFERROR(AVERAGEIFS(Trades!$P$4:$P$140,Trades!$N$4:$N$140,$A27,Trades!$R$4:$R$140,"<>Abierto"),0) -> 30.030303 | H27: =IF(B27=0,0,_xlfn.MAXIFS(Trades!$Q$4:$Q$140,Trades!$N$4:$N$140,$A27,Trades!$R$4:$R$140,"<>Abierto")) -> 0.12464722 | I27: =IF(B27=0,0,_xlfn.MINIFS(Trades!$Q$4:$Q$140,Trades!$N$4:$N$140,$A27,Trades!$R$4:$R$140,"<>Abierto")) -> -0.031068452
A28: ruptura piso Donchian + cae del ranking (>#5) | B28: =COUNTIFS(Trades!$N$4:$N$140,$A28,Trades!$R$4:$R$140,"<>Abierto") -> 2 | C28: =COUNTIFS(Trades!$N$4:$N$140,$A28,Trades!$R$4:$R$140,"Ganador") -> 0 | D28: =IFERROR(C28/B28,0) -> 0 | E28: =IFERROR(AVERAGEIFS(Trades!$Q$4:$Q$140,Trades!$N$4:$N$140,$A28,Trades!$R$4:$R$140,"<>Abierto"),0) -> -0.043020105 | F28: =SUMIFS(Trades!$Q$4:$Q$140,Trades!$N$4:$N$140,$A28,Trades!$R$4:$R$140,"<>Abierto") -> -0.08604021 | G28: =IFERROR(AVERAGEIFS(Trades!$P$4:$P$140,Trades!$N$4:$N$140,$A28,Trades!$R$4:$R$140,"<>Abierto"),0) -> 55.5 | H28: =IF(B28=0,0,_xlfn.MAXIFS(Trades!$Q$4:$Q$140,Trades!$N$4:$N$140,$A28,Trades!$R$4:$R$140,"<>Abierto")) -> -0.01590106 | I28: =IF(B28=0,0,_xlfn.MINIFS(Trades!$Q$4:$Q$140,Trades!$N$4:$N$140,$A28,Trades!$R$4:$R$140,"<>Abierto")) -> -0.07013915
A30: Por tramo de momentum 12m | B30: Trades | C30: Ganadores | D30: % Ganadores | E30: Retorno promedio | F30: Retorno acumulado | G30: Días promedio | H30: Mejor trade | I30: Peor trade
A31: =Parametros!B25 -> Negativo | B31: =COUNTIFS(Trades!$S$4:$S$140,$A31,Trades!$R$4:$R$140,"<>Abierto") -> 2 | C31: =COUNTIFS(Trades!$S$4:$S$140,$A31,Trades!$R$4:$R$140,"Ganador") -> 1 | D31: =IFERROR(C31/B31,0) -> 0.5 | E31: =IFERROR(AVERAGEIFS(Trades!$Q$4:$Q$140,Trades!$S$4:$S$140,$A31,Trades!$R$4:$R$140,"<>Abierto"),0) -> 0.012213204 | F31: =SUMIFS(Trades!$Q$4:$Q$140,Trades!$S$4:$S$140,$A31,Trades!$R$4:$R$140,"<>Abierto") -> 0.024426408 | G31: =IFERROR(AVERAGEIFS(Trades!$P$4:$P$140,Trades!$S$4:$S$140,$A31,Trades!$R$4:$R$140,"<>Abierto"),0) -> 60.5 | H31: =IF(B31=0,0,_xlfn.MAXIFS(Trades!$Q$4:$Q$140,Trades!$S$4:$S$140,$A31,Trades!$R$4:$R$140,"<>Abierto")) -> 0.038537712 | I31: =IF(B31=0,0,_xlfn.MINIFS(Trades!$Q$4:$Q$140,Trades!$S$4:$S$140,$A31,Trades!$R$4:$R$140,"<>Abierto")) -> -0.014111305
A32: =Parametros!B26 -> 0% a 5% | B32: =COUNTIFS(Trades!$S$4:$S$140,$A32,Trades!$R$4:$R$140,"<>Abierto") -> 7 | C32: =COUNTIFS(Trades!$S$4:$S$140,$A32,Trades!$R$4:$R$140,"Ganador") -> 5 | D32: =IFERROR(C32/B32,0) -> 0.71428571 | E32: =IFERROR(AVERAGEIFS(Trades!$Q$4:$Q$140,Trades!$S$4:$S$140,$A32,Trades!$R$4:$R$140,"<>Abierto"),0) -> 0.025746621 | F32: =SUMIFS(Trades!$Q$4:$Q$140,Trades!$S$4:$S$140,$A32,Trades!$R$4:$R$140,"<>Abierto") -> 0.18022635 | G32: =IFERROR(AVERAGEIFS(Trades!$P$4:$P$140,Trades!$S$4:$S$140,$A32,Trades!$R$4:$R$140,"<>Abierto"),0) -> 61.714286 | H32: =IF(B32=0,0,_xlfn.MAXIFS(Trades!$Q$4:$Q$140,Trades!$S$4:$S$140,$A32,Trades!$R$4:$R$140,"<>Abierto")) -> 0.074478989 | I32: =IF(B32=0,0,_xlfn.MINIFS(Trades!$Q$4:$Q$140,Trades!$S$4:$S$140,$A32,Trades!$R$4:$R$140,"<>Abierto")) -> -0.031068452
A33: =Parametros!B27 -> 5% a 15% | B33: =COUNTIFS(Trades!$S$4:$S$140,$A33,Trades!$R$4:$R$140,"<>Abierto") -> 18 | C33: =COUNTIFS(Trades!$S$4:$S$140,$A33,Trades!$R$4:$R$140,"Ganador") -> 12 | D33: =IFERROR(C33/B33,0) -> 0.66666667 | E33: =IFERROR(AVERAGEIFS(Trades!$Q$4:$Q$140,Trades!$S$4:$S$140,$A33,Trades!$R$4:$R$140,"<>Abierto"),0) -> 0.021043285 | F33: =SUMIFS(Trades!$Q$4:$Q$140,Trades!$S$4:$S$140,$A33,Trades!$R$4:$R$140,"<>Abierto") -> 0.37877913 | G33: =IFERROR(AVERAGEIFS(Trades!$P$4:$P$140,Trades!$S$4:$S$140,$A33,Trades!$R$4:$R$140,"<>Abierto"),0) -> 73.166667 | H33: =IF(B33=0,0,_xlfn.MAXIFS(Trades!$Q$4:$Q$140,Trades!$S$4:$S$140,$A33,Trades!$R$4:$R$140,"<>Abierto")) -> 0.19512195 | I33: =IF(B33=0,0,_xlfn.MINIFS(Trades!$Q$4:$Q$140,Trades!$S$4:$S$140,$A33,Trades!$R$4:$R$140,"<>Abierto")) -> -0.098686828
A34: =Parametros!B28 -> 15% a 30% | B34: =COUNTIFS(Trades!$S$4:$S$140,$A34,Trades!$R$4:$R$140,"<>Abierto") -> 59 | C34: =COUNTIFS(Trades!$S$4:$S$140,$A34,Trades!$R$4:$R$140,"Ganador") -> 28 | D34: =IFERROR(C34/B34,0) -> 0.47457627 | E34: =IFERROR(AVERAGEIFS(Trades!$Q$4:$Q$140,Trades!$S$4:$S$140,$A34,Trades!$R$4:$R$140,"<>Abierto"),0) -> 0.0051766278 | F34: =SUMIFS(Trades!$Q$4:$Q$140,Trades!$S$4:$S$140,$A34,Trades!$R$4:$R$140,"<>Abierto") -> 0.30542104 | G34: =IFERROR(AVERAGEIFS(Trades!$P$4:$P$140,Trades!$S$4:$S$140,$A34,Trades!$R$4:$R$140,"<>Abierto"),0) -> 53.152542 | H34: =IF(B34=0,0,_xlfn.MAXIFS(Trades!$Q$4:$Q$140,Trades!$S$4:$S$140,$A34,Trades!$R$4:$R$140,"<>Abierto")) -> 0.25961765 | I34: =IF(B34=0,0,_xlfn.MINIFS(Trades!$Q$4:$Q$140,Trades!$S$4:$S$140,$A34,Trades!$R$4:$R$140,"<>Abierto")) -> -0.096861798
A35: =Parametros!B29 -> Más de 30% | B35: =COUNTIFS(Trades!$S$4:$S$140,$A35,Trades!$R$4:$R$140,"<>Abierto") -> 50 | C35: =COUNTIFS(Trades!$S$4:$S$140,$A35,Trades!$R$4:$R$140,"Ganador") -> 21 | D35: =IFERROR(C35/B35,0) -> 0.42 | E35: =IFERROR(AVERAGEIFS(Trades!$Q$4:$Q$140,Trades!$S$4:$S$140,$A35,Trades!$R$4:$R$140,"<>Abierto"),0) -> 0.0083944396 | F35: =SUMIFS(Trades!$Q$4:$Q$140,Trades!$S$4:$S$140,$A35,Trades!$R$4:$R$140,"<>Abierto") -> 0.41972198 | G35: =IFERROR(AVERAGEIFS(Trades!$P$4:$P$140,Trades!$S$4:$S$140,$A35,Trades!$R$4:$R$140,"<>Abierto"),0) -> 53.74 | H35: =IF(B35=0,0,_xlfn.MAXIFS(Trades!$Q$4:$Q$140,Trades!$S$4:$S$140,$A35,Trades!$R$4:$R$140,"<>Abierto")) -> 0.25652174 | I35: =IF(B35=0,0,_xlfn.MINIFS(Trades!$Q$4:$Q$140,Trades!$S$4:$S$140,$A35,Trades!$R$4:$R$140,"<>Abierto")) -> -0.091493715
A37: Impacto de la comisión (costos de transacción)
A38: Comisión por compra y por venta en Parametros!B32. Retorno neto por trade = (salida×(1−c)) / (entrada×(1+c)) − 1. Solo trades cerrados.
A40: Por motivo de salida | B40: Trades | C40: Operaciones (compra+venta) | D40: Ret. acum. bruto | E40: Ret. acum. neto | F40: Costo comisión | G40: % del bruto que se pierde | H40: Costo promedio por trade | I40: % ganadores neto
A41: Todos | B41: =COUNTIFS(Trades!$R$4:$R$140,"<>Abierto") -> 136 | C41: =B41*2 -> 272 | D41: =SUMIFS(Trades!$Q$4:$Q$140,Trades!$R$4:$R$140,"<>Abierto") -> 1.3085749 | E41: =SUMIFS(Trades!$AE$4:$AE$140,Trades!$R$4:$R$140,"<>Abierto") -> 0.76043689 | F41: =D41-E41 -> 0.54813802 | G41: =IF(D41>0,F41/D41,"n/a") -> 0.41888165 | H41: =IFERROR(F41/B41,0) -> 0.0040304266 | I41: =IFERROR(COUNTIFS(Trades!$R$4:$R$140,"<>Abierto",Trades!$AE$4:$AE$140,">0")/B41,0) -> 0.42647059
A42: =A26 -> ruptura piso Donchian | B42: =COUNTIFS(Trades!$N$4:$N$140,$A42,Trades!$R$4:$R$140,"<>Abierto") -> 101 | C42: =B42*2 -> 202 | D42: =SUMIFS(Trades!$Q$4:$Q$140,Trades!$N$4:$N$140,$A42,Trades!$R$4:$R$140,"<>Abierto") -> 1.0610792 | E42: =SUMIFS(Trades!$AE$4:$AE$140,Trades!$N$4:$N$140,$A42,Trades!$R$4:$R$140,"<>Abierto") -> 0.65364971 | F42: =D42-E42 -> 0.40742946 | G42: =IF(D42>0,F42/D42,"n/a") -> 0.38397649 | H42: =IFERROR(F42/B42,0) -> 0.004033955 | I42: =IFERROR(COUNTIFS(Trades!$N$4:$N$140,$A42,Trades!$R$4:$R$140,"<>Abierto",Trades!$AE$4:$AE$140,">0")/B42,0) -> 0.43564356
A43: =A27 -> cae del ranking (>#5) | B43: =COUNTIFS(Trades!$N$4:$N$140,$A43,Trades!$R$4:$R$140,"<>Abierto") -> 33 | C43: =B43*2 -> 66 | D43: =SUMIFS(Trades!$Q$4:$Q$140,Trades!$N$4:$N$140,$A43,Trades!$R$4:$R$140,"<>Abierto") -> 0.33353595 | E43: =SUMIFS(Trades!$AE$4:$AE$140,Trades!$N$4:$N$140,$A43,Trades!$R$4:$R$140,"<>Abierto") -> 0.20046794 | F43: =D43-E43 -> 0.13306801 | G43: =IF(D43>0,F43/D43,"n/a") -> 0.39896151 | H43: =IFERROR(F43/B43,0) -> 0.0040323639 | I43: =IFERROR(COUNTIFS(Trades!$N$4:$N$140,$A43,Trades!$R$4:$R$140,"<>Abierto",Trades!$AE$4:$AE$140,">0")/B43,0) -> 0.42424242
A44: =A28 -> ruptura piso Donchian + cae del ranking (>#5) | B44: =COUNTIFS(Trades!$N$4:$N$140,$A44,Trades!$R$4:$R$140,"<>Abierto") -> 2 | C44: =B44*2 -> 4 | D44: =SUMIFS(Trades!$Q$4:$Q$140,Trades!$N$4:$N$140,$A44,Trades!$R$4:$R$140,"<>Abierto") -> -0.08604021 | E44: =SUMIFS(Trades!$AE$4:$AE$140,Trades!$N$4:$N$140,$A44,Trades!$R$4:$R$140,"<>Abierto") -> -0.093680768 | F44: =D44-E44 -> 0.007640558 | G44: =IF(D44>0,F44/D44,"n/a") -> n/a | H44: =IFERROR(F44/B44,0) -> 0.003820279 | I44: =IFERROR(COUNTIFS(Trades!$N$4:$N$140,$A44,Trades!$R$4:$R$140,"<>Abierto",Trades!$AE$4:$AE$140,">0")/B44,0) -> 0
A45: Peso de Donchian en el costo total | B45: =(F42+F44)/F41 -> 0.75723631
A47: Impacto a nivel cartera | B47: Valor
A48: Período analizado (años) | B48: =(MAX(Trades!$K$4:$K$140)-MIN(Trades!$D$4:$D$140))/365.25 -> 10.540726
...

Sheet Whipsaws
A1: Whipsaws: salida seguida de reentrada del mismo activo dentro de la ventana
A2: Costo = cierre de reentrada / cierre de salida − 1. Positivo = se recompró más caro de lo que se vendió (costo); negativo = se recompró más barato.
A4: Resumen | B4: Valor | D4: Por motivo de salida | E4: Whipsaws | F4: Costo promedio | G4: Costo acumulado
A5: Ventana (días) | B5: =Parametros!B4 -> 10 | D5: ruptura piso Donchian | E5: =COUNTIFS(Trades!$Y$4:$Y$140,"Sí",Trades!$N$4:$N$140,$D5) -> 3 | F5: =IFERROR(AVERAGEIFS(Trades!$Z$4:$Z$140,Trades!$Y$4:$Y$140,"Sí",Trades!$N$4:$N$140,$D5),0) -> 0.049355944 | G5: =SUMIFS(Trades!$Z$4:$Z$140,Trades!$Y$4:$Y$140,"Sí",Trades!$N$4:$N$140,$D5) -> 0.14806783
A6: Cantidad de whipsaws | B6: =COUNTIF(Trades!$Y$4:$Y$140,"Sí") -> 6 | D6: cae del ranking (>#5) | E6: =COUNTIFS(Trades!$Y$4:$Y$140,"Sí",Trades!$N$4:$N$140,$D6) -> 3 | F6: =IFERROR(AVERAGEIFS(Trades!$Z$4:$Z$140,Trades!$Y$4:$Y$140,"Sí",Trades!$N$4:$N$140,$D6),0) -> 0.032854572 | G6: =SUMIFS(Trades!$Z$4:$Z$140,Trades!$Y$4:$Y$140,"Sí",Trades!$N$4:$N$140,$D6) -> 0.098563717
A7: % de las salidas cerradas | B7: =IFERROR(B6/COUNTIF(Trades!$R$4:$R$140,"<>Abierto"),0) -> 0.044117647 | D7: ruptura piso Donchian + cae del ranking (>#5) | E7: =COUNTIFS(Trades!$Y$4:$Y$140,"Sí",Trades!$N$4:$N$140,$D7) -> 0 | F7: =IFERROR(AVERAGEIFS(Trades!$Z$4:$Z$140,Trades!$Y$4:$Y$140,"Sí",Trades!$N$4:$N$140,$D7),0) -> 0 | G7: =SUMIFS(Trades!$Z$4:$Z$140,Trades!$Y$4:$Y$140,"Sí",Trades!$N$4:$N$140,$D7) -> 0
A8: Costo promedio por whipsaw | B8: =IFERROR(AVERAGEIF(Trades!$Y$4:$Y$140,"Sí",Trades!$Z$4:$Z$140),0) -> 0.041105258
A9: Costo acumulado (suma) | B9: =SUMIF(Trades!$Y$4:$Y$140,"Sí",Trades!$Z$4:$Z$140) -> 0.24663155
A10: Whipsaws con costo (recompra más cara) | B10: =COUNTIFS(Trades!$Y$4:$Y$140,"Sí",Trades!$Z$4:$Z$140,">0") -> 6
A13: # Trade | B13: Activo | C13: Fecha entrada | D13: Fecha salida | E13: Motivo salida | F13: Rank salida | G13: Cierre salida | H13: Dist. al piso en salida | I13: Fecha reentrada | J13: Cierre reentrada | K13: Días hasta reentrada | L13: Costo whipsaw | M13: Retorno del trade
A14: {=IFERROR(_xlfn.AGGREGATE(15,6,(ROW(Trades!$Y$4:$Y$140)-3)/(Trades!$Y$4:$Y$140="Sí"),ROW()-13),"")} -> 72 | B14: {=IF($A14="","",INDEX(Trades!$C:$C,$A14+3))} -> XLRE | C14: {=IF($A14="","",INDEX(Trades!$D:$D,$A14+3))} -> 44491 | D14: {=IF($A14="","",INDEX(Trades!$K:$K,$A14+3))} -> 44531 | E14: {=IF($A14="","",INDEX(Trades!$N:$N,$A14+3))} -> ruptura piso Donchian | F14: {=IF($A14="","",INDEX(Trades!$O:$O,$A14+3))} -> 4 | G14: {=IF($A14="","",INDEX(Trades!$L:$L,$A14+3))} -> 39.79 | H14: {=IF($A14="","",INDEX(Trades!$T:$T,$A14+3))} -> -0.012655087 | I14: {=IF($A14="","",INDEX(Trades!$V:$V,$A14+3))} -> 44537 | J14: {=IF($A14="","",INDEX(Trades!$X:$X,$A14+3))} -> 41.99 | K14: {=IF($A14="","",INDEX(Trades!$W:$W,$A14+3))} -> 6 | L14: {=IF($A14="","",INDEX(Trades!$Z:$Z,$A14+3))} -> 0.055290274 | M14: {=IF($A14="","",INDEX(Trades!$Q:$Q,$A14+3))} -> -0.019226029
A15: {=IFERROR(_xlfn.AGGREGATE(15,6,(ROW(Trades!$Y$4:$Y$140)-3)/(Trades!$Y$4:$Y$140="Sí"),ROW()-13),"")} -> 101 | B15: {=IF($A15="","",INDEX(Trades!$C:$C,$A15+3))} -> XLY | C15: {=IF($A15="","",INDEX(Trades!$D:$D,$A15+3))} -> 45244 | D15: {=IF($A15="","",INDEX(Trades!$K:$K,$A15+3))} -> 45316 | E15: {=IF($A15="","",INDEX(Trades!$N:$N,$A15+3))} -> ruptura piso Donchian | F15: {=IF($A15="","",INDEX(Trades!$O:$O,$A15+3))} -> 3 | G15: {=IF($A15="","",INDEX(Trades!$L:$L,$A15+3))} -> 83.68 | H15: {=IF($A15="","",INDEX(Trades!$T:$T,$A15+3))} -> -0.00035838012 | I15: {=IF($A15="","",INDEX(Trades!$V:$V,$A15+3))} -> 45324 | J15: {=IF($A15="","",INDEX(Trades!$X:$X,$A15+3))} -> 86.83 | K15: {=IF($A15="","",INDEX(Trades!$W:$W,$A15+3))} -> 8 | L15: {=IF($A15="","",INDEX(Trades!$Z:$Z,$A15+3))} -> 0.037643403 | M15: {=IF($A15="","",INDEX(Trades!$Q:$Q,$A15+3))} -> 0.021733822
